Workbook
Name inc_id: INCIDENTS!$A$2:$A$500
Name inc_date: INCIDENTS!$B$2:$B$500
Name inc_periode: INCIDENTS!$D$2:$D$500
Name inc_region: INCIDENTS!$F$2:$F$500
Name inc_cercle: INCIDENTS!$G$2:$G$500
Name inc_mode: INCIDENTS!$N$2:$N$500
Name inc_acteur: INCIDENTS!$O$2:$O$500
Name inc_cible: INCIDENTS!$Q$2:$Q$500
Name inc_civ_k: INCIDENTS!$T$2:$T$500
Name inc_civ_w: INCIDENTS!$U$2:$U$500
Name inc_fama: INCIDENTS!$V$2:$V$500
Name inc_ac: INCIDENTS!$W$2:$W$500
Name inc_ga: INCIDENTS!$X$2:$X$500
Name inc_tues: INCIDENTS!$Y$2:$Y$500
Name inc_pow: INCIDENTS!$Z$2:$Z$500
Name inc_vehd: INCIDENTS!$AA$2:$AA$500
Name inc_vehs: INCIDENTS!$AB$2:$AB$500
Name inc_dist: INCIDENTS!$AE$2:$AE$500
Name inc_rayon: INCIDENTS!$AF$2:$AF$500
Name inc_fiab: INCIDENTS!$AG$2:$AG$500
Name inc_sources: INCIDENTS!$AI$2:$AI$500
Name inc_revend: INCIDENTS!$AH$2:$AH$500
Name inc_prec: INCIDENTS!$L$2:$L$500
Name P_DEBUT: PARAMETRES!$C$5
Name P_FIN: PARAMETRES!$C$6
Name P_DEBUT_P2: PARAMETRES!$C$7
Name LAT_BAMAKO: PARAMETRES!$C$9
Name LON_BAMAKO: PARAMETRES!$C$10
Name SEUIL_KM: PARAMETRES!$C$11
Name URL_TABLEAU: PARAMETRES!$C$13
Name FICHIER_HTML: PARAMETRES!$C$14
Name FEN_RECENTE: PARAMETRES!$C$16
Name W_FREQ: PARAMETRES!$C$17
Name W_LETAL: PARAMETRES!$C$18
Name W_CIVILS: PARAMETRES!$C$19
Name W_RECENT: PARAMETRES!$C$20
Name S_CRITIQUE: PARAMETRES!$C$21
Name S_ELEVE: PARAMETRES!$C$22
Name S_MODERE: PARAMETRES!$C$23

Sheet ACCUEIL
A1: OBSERVATOIRE SÉCURITAIRE · MALI — Tableau de bord décisionnel
A2: Période du 31/08/2026 au 26/10/2026 · Sources ouvertes · Diffusion restreinte · Généré le 29/10/2026
B4: Indicateurs clés (calculés depuis INCIDENTS)
B5: INCIDENTS | D5: TUÉS (TOTAL) | F5: FDS (FAMA) TUÉS | H5: AFRICA CORPS TUÉS | J5: COMBATTANTS ARMÉS TUÉS | L5: CIVILS TUÉS
B6: =COUNTA(inc_id) | D6: =SUM(inc_tues) | F6: =SUM(inc_fama) | H6: =SUM(inc_ac) | J6: =SUM(inc_ga) | L6: =SUM(inc_civ_k)
B8: CIVILS BLESSÉS | D8: CAPTURÉS | F8: VÉH. / AÉRONEFS DÉTRUITS | H8: VÉH. / AÉRONEFS SAISIS | J8: DANS LE RAYON DE BAMAKO | L8: PART DU JNIM
B9: =SUM(inc_civ_w) | D9: =SUM(inc_pow) | F9: =SUM(inc_vehd) | H9: =SUM(inc_vehs) | J9: =COUNTIFS(inc_rayon,"Oui") | L9: =IF(COUNTA(inc_id)=0,0,COUNTIFS(inc_acteur,"JNIM")/COUNTA(inc_id))
B12: Accès à la cartographie
B13: =HYPERLINK(URL_TABLEAU,"▶ Ouvrir le tableau de bord et la carte interactive (en ligne)") | H13: Carte WebGL, filtres, animation chronologique, dossiers d'incidents. Nécessite Internet ; lien privé à partager depuis la page.
B14: =HYPERLINK(FICHIER_HTML,"▶ Ouvrir la version locale (fichier HTML)") | H14: Le fichier « tableau_de_bord_mali.html » doit être dans le même dossier que ce classeur. Internet requis pour charger le moteur cartographique.
B15: ▶ Cartes de situation (onglet CARTES) | H15: Voir les cartes de situation intégrées au classeur (consultables hors ligne et imprimables).
B16: ▶ Registre des incidents avec liens cartographiques | H16: Chaque incident possède des liens « OSM ↗ », « Google ↗ » et « Dossier ↗ » (colonnes AJ à AL de INCIDENTS).
B18: L'essentiel
B19: Le JNIM mène l'initiative. | F19: 21 des 36 incidents (58 %), dont 16 à Ségou et Mopti ; à l'origine de 92 % des FDS maliennes tuées (192 sur 208).
B20: La pression se rapproche de Bamako. | F20: 9 incidents à moins de 300 km, dont un poste pris à Kassela (32 km). Six attaques visent des axes routiers : asphyxie logistique.
B21: Les frappes aériennes causent toutes les morts civiles recensées. | F21: 28 civils tués sur 28 lors de quatre frappes FAMa / Africa Corps ; ×3 entre P1 et P2 (7 → 21).
B22: La guerre JNIM – EI-Sahel saigne le Liptako. | F22: Deux batailles revendiquées : 600 tués, 64 % de la létalité de la base. Bilans à confirmer (double comptage possible).
B24: Sommaire
B25: CARTES | D25: Cartes de situation (3 cartes) | H25: PRESSION_BAMAKO | J25: Distance à la capitale
B26: INCIDENTS | D26: Registre enrichi des 36 incidents, liens cartographiques | H26: EVALUATION | J26: Jugements clés, scénarios, alertes, recommandations
B27: REGIONS | D27: Synthèse régionale et indice de menace | H27: QUALITE_SOURCES | J27: Fiabilité, sources, limites
B28: ACTEURS | D28: Synthèse par acteur, matrice acteur × mode | H28: PARAMETRES | J28: Hypothèses modifiables (période, rayon, poids de l'indice)
B29: CHRONOLOGIE | D29: Rythme hebdomadaire, comparaison P1 / P2 | H29: MODE_EMPLOI | J29: Ouvrir la carte depuis Excel, résolution des problèmes
B30: MODES_CIBLES | D30: Modes opératoires et cibles | H30: DICTIONNAIRE | J30: Définition des colonnes
B31: Carte de situation — cliquez « Ouvrir le tableau de bord » pour la version interactive

Sheet CARTES
A1: Cartes de situation | R1: ◄ Accueil
A2: Instantanés du tableau de bord interactif. Pour zoomer, filtrer et animer : liens ci-dessous.
B4: =HYPERLINK(URL_TABLEAU,"▶ Ouvrir la carte interactive (en ligne)") | G4: =HYPERLINK(FICHIER_HTML,"▶ Ouvrir le fichier HTML local (même dossier)") | L4: =HYPERLINK("https://www.openstreetmap.org/#map=6/16.5/-3.5","▶ Fond OpenStreetMap du Mali")
B6: Carte 1 — Situation générale : incidents par acteur (taille ∝ √ tués), indice de menace régional, axes routiers, fleuve Niger, rayons de 50 / 150 / 300 km autour de Bamako.
B44: Carte 2 — Zoom Mali central (Koulikoro – Ségou – Mopti) : guerre des axes et pression sur Bamako.
B82: Carte 3 — Densité 3D : hexagones de 30 km, hauteur et couleur = Σ(1 + √tués).
B120: Fonds : geoBoundaries (CC BY 4.0), Natural Earth. Données : compilations Naïm TOURÉ, 31/08 – 26/10/2026.

Sheet INCIDENTS
A1: ID | B1: Date | C1: Semaine ISO | D1: Période | E1: Pays (géocodé) | F1: Région (géocodée) | G1: Cercle (géocodé) | H1: Région déclarée | I1: Localité | J1: Latitude | K1: Longitude | L1: Précision géo. | M1: Typologie (source) | N1: Mode opératoire | O1: Instigateur | P1: Instigateur (détail) | Q1: Cible | R1: Cible (détail) | S1: Description | T1: Morts civils | U1: Blessés civils | V1: Morts FDS (FAMa) | W1: Morts Africa Corps | X1: Morts groupes armés | Y1: Total tués | Z1: Capturés | AA1: Véh./aéronefs détruits | AB1: Véh./aéronefs saisis | AC1: Armement / équipement saisi | AD1: Impact | AE1: Distance Bamako (km) | AF1: Dans le rayon Bamako | AG1: Fiabilité | AH1: Bilan revendiqué seul | AI1: Sources | AJ1: Carte OSM | AK1: Google Maps | AL1: Tableau de bord
A2: INC-2026-001 | B2: 46265 | C2: =WEEKNUM(B2,21) | D2: =IF(B2<P_DEBUT_P2,"P1","P2") | E2: Mali | F2: Mopti | G2: Bandiagara | H2: Mopti / Bandiagara | I2: NINNGARI | J2: 14.35 | K2: -3.6167 | L2: Localité | M2: Attaque de Poste / Localité | N2: Attaque de poste / camp | O2: JNIM | P2: JNIM | Q2: Milices pro-gouv. | R2: Milices Dozos | S2: Le JNIM a attaqué la localité stratégique de NINNGARI à Bandiagara et en a pris le contrôle total. | T2: 0 | U2: 0 | V2: 0 | W2: 0 | X2: 0 | Y2: =T2+V2+W2+X2 | Z2: 0 | AA2: 0 | AB2: 0 | AC2: Non spécifié | AD2: Prise de contrôle de la localité | AE2: =ROUND(2*6371*ASIN(SQRT(SIN(RADIANS(J2-LAT_BAMAKO)/2)^2+COS(RADIANS(LAT_BAMAKO))*COS(RADIANS(J2))*SIN(RADIANS(K2-LON_BAMAKO)/2)^2)),0) | AF2: =IF(AE2<=SEUIL_KM,"Oui","Non") | AG2: Partiellement corroboré | AH2: Non | AI2: AzZalaqa, Hasret K., Naïm TOURÉ | AJ2: =HYPERLINK("https://www.openstreetmap.org/?mlat="&SUBSTITUTE(J2&"",",",".")&"&mlon="&SUBSTITUTE(K2&"",",",".")&"#map=11/"&SUBSTITUTE(J2&"",",",".")&"/"&SUBSTITUTE(K2&"",",","."),"OSM ↗") | AK2: =HYPERLINK("https://www.google.com/maps/search/?api=1&query="&SUBSTITUTE(J2&"",",",".")&"%2C"&SUBSTITUTE(K2&"",",","."),"Google ↗") | AL2: =HYPERLINK(URL_TABLEAU&"#"&A2,"Dossier ↗")
A3: INC-2026-002 | B3: 46265 | C3: =WEEKNUM(B3,21) | D3: =IF(B3<P_DEBUT_P2,"P1","P2") | E3: Mali | F3: Kidal | G3: Tessalit | H3: Kidal | I3: Aguelhoc / Kidal | J3: 19.4633 | K3: 0.8552 | L3: Localité | M3: Frappe Drone / Air | N3: Drone armé (FPV) | O3: FLA | P3: FLA / Armée de l'Azawad | Q3: FAMa / Africa Corps | R3: FAMa / Africa Corps | S3: L’Armée de l’Azawad a mené plusieurs frappes de drones FPV contre le camp conjoint Africa Corps et FAMa. | T3: 0 | U3: 0 | V3: 0 | W3: 0 | X3: 0 | Y3: =T3+V3+W3+X3 | Z3: 0 | AA3: 0 | AB3: 0 | AC3: Non spécifié | AD3: Camp militaire ciblé par drones FPV | AE3: =ROUND(2*6371*ASIN(SQRT(SIN(RADIANS(J3-LAT_BAMAKO)/2)^2+COS(RADIANS(LAT_BAMAKO))*COS(RADIANS(J3))*SIN(RADIANS(K3-LON_BAMAKO)/2)^2)),0) | AF3: =IF(AE3<=SEUIL_KM,"Oui","Non") | AG3: Source partisane seule | AH3: Non | AI3: FLA, Naïm TOURÉ | AJ3: =HYPERLINK("https://www.openstreetmap.org/?mlat="&SUBSTITUTE(J3&"",",",".")&"&mlon="&SUBSTITUTE(K3&"",",",".")&"#map=11/"&SUBSTITUTE(J3&"",",",".")&"/"&SUBSTITUTE(K3&"",",","."),"OSM ↗") | AK3: =HYPERLINK("https://www.google.com/maps/search/?api=1&query="&SUBSTITUTE(J3&"",",",".")&"%2C"&SUBSTITUTE(K3&"",",","."),"Google ↗") | AL3: =HYPERLINK(URL_TABLEAU&"#"&A3,"Dossier ↗")
A4: INC-2026-003 | B4: 46266 | C4: =WEEKNUM(B4,21) | D4: =IF(B4<P_DEBUT_P2,"P1","P2") | E4: Mali | F4: Tombouctou | G4: Gourma-Rharous | H4: Frontière Mali-Burkina (Oudalan / Ndaki) | I4: Gonadaouri / Ndaki | J4: 15.2833 | K4: -1.1833 | L4: Localité | M4: Affrontement Inter-JNIM-EIS | N4: Affrontement JNIM–EIS | O4: EI-Sahel | P4: EI-Sahel (EIS) | Q4: Groupes armés | R4: JNIM | S4: Violents affrontements entre l'EI-Sahel et le JNIM. L'EI-Sahel affirme avoir tué plus de 200 à 400 combattants du JNIM et capturé un vaste territoire frontalier. | T4: 0 | U4: 0 | V4: 0 | W4: 0 | X4: 200 | Y4: =T4+V4+W4+X4 | Z4: 30 | AA4: 100 | AB4: 204 | AC4: 242 fusils, importantes munitions | AD4: Contrôle territorial modifié le long de la frontière | AE4: =ROUND(2*6371*ASIN(SQRT(SIN(RADIANS(J4-LAT_BAMAKO)/2)^2+COS(RADIANS(LAT_BAMAKO))*COS(RADIANS(J4))*SIN(RADIANS(K4-LON_BAMAKO)/2)^2)),0) | AF4: =IF(AE4<=SEUIL_KM,"Oui","Non") | AG4: Partiellement corroboré | AH4: Non | AI4: EIS, Brant P., JNIM, Naïm TOURÉ | AJ4: =HYPERLINK("https://www.openstreetmap.org/?mlat="&SUBSTITUTE(J4&"",",",".")&"&mlon="&SUBSTITUTE(K4&"",",",".")&"#map=11/"&SUBSTITUTE(J4&"",",",".")&"/"&SUBSTITUTE(K4&"",",","."),"OSM ↗") | AK4: =HYPERLINK("https://www.google.com/maps/search/?api=1&query="&SUBSTITUTE(J4&"",",",".")&"%2C"&SUBSTITUTE(K4&"",",","."),"Google ↗") | AL4: =HYPERLINK(URL_TABLEAU&"#"&A4,"Dossier ↗")
A5: INC-2026-004 | B5: 46267 | C5: =WEEKNUM(B5,21) | D5: =IF(B5<P_DEBUT_P2,"P1","P2") | E5: Mali | F5: Ségou | G5: Ségou | H5: Ségou | I5: Axe Ségou - Fana | J5: 13.35 | K5: -6.3 | L5: Zone (±10 km) | M5: Sabotage / Incendie de Convoi | N5: Sabotage logistique | O5: JNIM | P5: JNIM | Q5: Logistique civile | R5: Transport commercial / Citernes | S5: Des combattants du JNIM ont incendié plusieurs citernes de carburant sur l'axe Ségou-Fana. | T5: 0 | U5: 0 | V5: 0 | W5: 0 | X5: 0 | Y5: =T5+V5+W5+X5 | Z5: 0 | AA5: 3 | AB5: 0 | AC5: Aucun | AD5: Axe routier Ségou-Fana perturbé, citernes détruites | AE5: =ROUND(2*6371*ASIN(SQRT(SIN(RADIANS(J5-LAT_BAMAKO)/2)^2+COS(RADIANS(LAT_BAMAKO))*COS(RADIANS(J5))*SIN(RADIANS(K5-LON_BAMAKO)/2)^2)),0) | AF5: =IF(AE5<=SEUIL_KM,"Oui","Non") | AG5: Partiellement corroboré | AH5: Non | AI5: Sagnon, Naïm TOURÉ | AJ5: =HYPERLINK("https://www.openstreetmap.org/?mlat="&SUBSTITUTE(J5&"",",",".")&"&mlon="&SUBSTITUTE(K5&"",",",".")&"#map=11/"&SUBSTITUTE(J5&"",",",".")&"/"&SUBSTITUTE(K5&"",",","."),"OSM ↗") | AK5: =HYPERLINK("https://www.google.com/maps/search/?api=1&query="&SUBSTITUTE(J5&"",",",".")&"%2C"&SUBSTITUTE(K5&"",",","."),"Google ↗") | AL5: =HYPERLINK(URL_TABLEAU&"#"&A5,"Dossier ↗")
A6: INC-2026-005 | B6: 46269 | C6: =WEEKNUM(B6,21) | D6: =IF(B6<P_DEBUT_P2,"P1","P2") | E6: Mali | F6: Kidal | G6: Kidal | H6: Kidal | I6: Kidal Ville | J6: 18.4411 | K6: 1.4078 | L6: Localité | M6: Bombardement Aérien | N6: Frappe aérienne étatique | O6: FAMa / Africa Corps | P6: Africa Corps / FAMa | Q6: Civils | R6: Résidence du Maire de Kidal | S6: Un avion de chasse Sukhoï 24 appartenant à Africa Corps a bombardé la résidence du maire de Kidal. | T6: 0 | U6: 0 | V6: 0 | W6: 0 | X6: 0 | Y6: =T6+V6+W6+X6 | Z6: 0 | AA6: 0 | AB6: 0 | AC6: Aucun | AD6: Résidence du maire pilonnée | AE6: =ROUND(2*6371*ASIN(SQRT(SIN(RADIANS(J6-LAT_BAMAKO)/2)^2+COS(RADIANS(LAT_BAMAKO))*COS(RADIANS(J6))*SIN(RADIANS(K6-LON_BAMAKO)/2)^2)),0) | AF6: =IF(AE6<=SEUIL_KM,"Oui","Non") | AG6: Partiellement corroboré | AH6: Non | AI6: Outamashaq, Naïm TOURÉ | AJ6: =HYPERLINK("https://www.openstreetmap.org/?mlat="&SUBSTITUTE(J6&"",",",".")&"&mlon="&SUBSTITUTE(K6&"",",",".")&"#map=11/"&SUBSTITUTE(J6&"",",",".")&"/"&SUBSTITUTE(K6&"",",","."),"OSM ↗") | AK6: =HYPERLINK("https://www.google.com/maps/search/?api=1&query="&SUBSTITUTE(J6&"",",",".")&"%2C"&SUBSTITUTE(K6&"",",","."),"Google ↗") | AL6: =HYPERLINK(URL_TABLEAU&"#"&A6,"Dossier ↗")
A7: INC-2026-006 | B7: 46272 | C7: =WEEKNUM(B7,21) | D7: =IF(B7<P_DEBUT_P2,"P1","P2") | E7: Mali | F7: Mopti | G7: Bandiagara | H7: Mopti | I7: Kaka | J7: 14.8 | K7: -3.8 | L7: Zone (±10 km) | M7: Embuscade | N7: Embuscade | O7: JNIM | P7: JNIM | Q7: FAMa / Africa Corps | R7: FAMa / Africa Corps | S7: Embuscade du JNIM contre une patrouille conjointe FAMa et Africa Corps. Plusieurs mercenaires russes tués. | T7: 0 | U7: 0 | V7: 0 | W7: 4 | X7: 0 | Y7: =T7+V7+W7+X7 | Z7: 0 | AA7: 0 | AB7: 0 | AC7: Non spécifié | AD7: Convoi militaire stoppé | AE7: =ROUND(2*6371*ASIN(SQRT(SIN(RADIANS(J7-LAT_BAMAKO)/2)^2+COS(RADIANS(LAT_BAMAKO))*COS(RADIANS(J7))*SIN(RADIANS(K7-LON_BAMAKO)/2)^2)),0) | AF7: =IF(AE7<=SEUIL_KM,"Oui","Non") | AG7: Partiellement corroboré | AH7: Non | AI7: Sahel Alerte, Naïm TOURÉ | AJ7: =HYPERLINK("https://www.openstreetmap.org/?mlat="&SUBSTITUTE(J7&"",",",".")&"&mlon="&SUBSTITUTE(K7&"",",",".")&"#map=11/"&SUBSTITUTE(J7&"",",",".")&"/"&SUBSTITUTE(K7&"",",","."),"OSM ↗") | AK7: =HYPERLINK("https://www.google.com/maps/search/?api=1&query="&SUBSTITUTE(J7&"",",",".")&"%2C"&SUBSTITUTE(K7&"",",","."),"Google ↗") | AL7: =HYPERLINK(URL_TABLEAU&"#"&A7,"Dossier ↗")
A8: INC-2026-007 | B8: 46275 | C8: =WEEKNUM(B8,21) | D8: =IF(B8<P_DEBUT_P2,"P1","P2") | E8: Mali | F8: Mopti | G8: Ténenkou | H8: Mopti | I8: Dioura | J8: 14.5333 | K8: -5.2167 | L8: Localité | M8: Attaque Majeure de Camp / Base | N8: Attaque de poste / camp | O8: JNIM | P8: JNIM (Abou Mokhtar al-Ansari) | Q8: FAMa / Africa Corps | R8: FAMa (Camp militaire) | S8: Prise du camp de Dioura par le JNIM. Attaque dévastatrice avec plus de 150 soldats tués (dont 1 Colonel et 1 Capitaine) et 93 capturés. | T8: 0 | U8: 0 | V8: 150 | W8: 0 | X8: 0 | Y8: =T8+V8+W8+X8 | Z8: 93 | AA8: 115 | AB8: 16 | AC8: 233 Kalachnikovs, 32 PKM, 17 Doushka, 10 RPG, 6 x 14mm, 3 mortiers/SPG, munitions | AD8: Camp militaire de Dioura détruit et pris | AE8: =ROUND(2*6371*ASIN(SQRT(SIN(RADIANS(J8-LAT_BAMAKO)/2)^2+COS(RADIANS(LAT_BAMAKO))*COS(RADIANS(J8))*SIN(RADIANS(K8-LON_BAMAKO)/2)^2)),0) | AF8: =IF(AE8<=SEUIL_KM,"Oui","Non") | AG8: Corroboré | AH8: Non | AI8: AzZalaqa, Hasret K., Sahel Alerte, Naïm TOURÉ | AJ8: =HYPERLINK("https://www.openstreetmap.org/?mlat="&SUBSTITUTE(J8&"",",",".")&"&mlon="&SUBSTITUTE(K8&"",",",".")&"#map=11/"&SUBSTITUTE(J8&"",",",".")&"/"&SUBSTITUTE(K8&"",",","."),"OSM ↗") | AK8: =HYPERLINK("https://www.google.com/maps/search/?api=1&query="&SUBSTITUTE(J8&"",",",".")&"%2C"&SUBSTITUTE(K8&"",",","."),"Google ↗") | AL8: =HYPERLINK(URL_TABLEAU&"#"&A8,"Dossier ↗")
A9: INC-2026-008 | B9: 46279 | C9: =WEEKNUM(B9,21) | D9: =IF(B9<P_DEBUT_P2,"P1","P2") | E9: Mali | F9: Koulikoro | G9: Nara | H9: Koulikoro | I9: Axe Mourdja - Kaloumba | J9: 14.4833 | K9: -7.4667 | L9: Localité | M9: Engin Explosif Improvisé (EEI) | N9: EEI | O9: JNIM | P9: JNIM | Q9: FAMa / Africa Corps | R9: FAMa / Africa Corps | S9: Attaque à l'EEI visant une patrouille mixte FAMa-Africa Corps sur l'axe Mourdja-Kaloumba. | T9: 0 | U9: 0 | V9: 2 | W9: 2 | X9: 0 | Y9: =T9+V9+W9+X9 | Z9: 0 | AA9: 1 | AB9: 0 | AC9: Aucun | AD9: Véhicule militaire touché par EEI | AE9: =ROUND(2*6371*ASIN(SQRT(SIN(RADIANS(J9-LAT_BAMAKO)/2)^2+COS(RADIANS(LAT_BAMAKO))*COS(RADIANS(J9))*SIN(RADIANS(K9-LON_BAMAKO)/2)^2)),0) | AF9: =IF(AE9<=SEUIL_KM,"Oui","Non") | AG9: Partiellement corroboré | AH9: Non | AI9: Sahel Alerte, Naïm TOURÉ | AJ9: =HYPERLINK("https://www.openstreetmap.org/?mlat="&SUBSTITUTE(J9&"",",",".")&"&mlon="&SUBSTITUTE(K9&"",",",".")&"#map=11/"&SUBSTITUTE(J9&"",",",".")&"/"&SUBSTITUTE(K9&"",",","."),"OSM ↗") | AK9: =HYPERLINK("https://www.google.com/maps/search/?api=1&query="&SUBSTITUTE(J9&"",",",".")&"%2C"&SUBSTITUTE(K9&"",",","."),"Google ↗") | AL9: =HYPERLINK(URL_TABLEAU&"#"&A9,"Dossier ↗")
A10: INC-2026-009 | B10: 46280 | C10: =WEEKNUM(B10,21) | D10: =IF(B10<P_DEBUT_P2,"P1","P2") | E10: Mali | F10: Mopti | G10: Mopti | H10: Mopti | I10: Aéroport de Sévaré / Konna | J10: 14.5133 | K10: -4.1033 | L10: Localité | M10: Tirs de Mortier / Artillerie | N10: Tirs indirects | O10: JNIM | P10: JNIM | Q10: FAMa / Africa Corps | R10: Base Aérienne FAMa / Africa Corps | S10: Tirs de mortiers et canons SPG-9 contre la base de Sévaré et Konna. 4 drones (Bayraktar TB2 / Akıncı) et plusieurs hélicoptères endommagés. Tour radar détruite. | T10: 0 | U10: 0 | V10: 15 | W10: 18 | X10: 0 | Y10: =T10+V10+W10+X10 | Z10: 0 | AA10: 6 | AB10: 0 | AC10: Aucun | AD10: Tour de contrôle réseau drone et radar détruits | AE10: =ROUND(2*6371*ASIN(SQRT(SIN(RADIANS(J10-LAT_BAMAKO)/2)^2+COS(RADIANS(LAT_BAMAKO))*COS(RADIANS(J10))*SIN(RADIANS(K10-LON_BAMAKO)/2)^2)),0) | AF10: =IF(AE10<=SEUIL_KM,"Oui","Non") | AG10: Corroboré | AH10: Non | AI10: AzZalaqa, Hasret K., Sahel Alerte, Naïm TOURÉ | AJ10: =HYPERLINK("https://www.openstreetmap.org/?mlat="&SUBSTITUTE(J10&"",",",".")&"&mlon="&SUBSTITUTE(K10&"",",",".")&"#map=11/"&SUBSTITUTE(J10&"",",",".")&"/"&SUBSTITUTE(K10&"",",","."),"OSM ↗") | AK10: =HYPERLINK("https://www.google.com/maps/search/?api=1&query="&SUBSTITUTE(J10&"",",",".")&"%2C"&SUBSTITUTE(K10&"",",","."),"Google ↗") | AL10: =HYPERLINK(URL_TABLEAU&"#"&A10,"Dossier ↗")
A11: INC-2026-010 | B11: 46281 | C11: =WEEKNUM(B11,21) | D11: =IF(B11<P_DEBUT_P2,"P1","P2") | E11: Mali | F11: Mopti | G11: Ténenkou | H11: Mopti / Ténenkou | I11: Guèllèdjè | J11: 14.45 | K11: -4.9167 | L11: Localité | M11: Frappe Drone / Bavure Civile | N11: Frappe aérienne étatique | O11: FAMa / Africa Corps | P11: FAMa / Africa Corps (Drone) | Q11: Civils | R11: Point de connexion Starlink (Civils) | S11: Bombardement par un drone militaire sur un point d'accès Starlink dans le village de Guèllèdjè. | T11: 7 | U11: 8 | V11: 0 | W11: 0 | X11: 0 | Y11: =T11+V11+W11+X11 | Z11: 0 | AA11: 0 | AB11: 0 | AC11: Aucun | AD11: Station Starlink civile détruite | AE11: =ROUND(2*6371*ASIN(SQRT(SIN(RADIANS(J11-LAT_BAMAKO)/2)^2+COS(RADIANS(LAT_BAMAKO))*COS(RADIANS(J11))*SIN(RADIANS(K11-LON_BAMAKO)/2)^2)),0) | AF11: =IF(AE11<=SEUIL_KM,"Oui","Non") | AG11: Source unique | AH11: Oui | AI11: Naïm TOURÉ | AJ11: =HYPERLINK("https://www.openstreetmap.org/?mlat="&SUBSTITUTE(J11&"",",",".")&"&mlon="&SUBSTITUTE(K11&"",",",".")&"#map=11/"&SUBSTITUTE(J11&"",",",".")&"/"&SUBSTITUTE(K11&"",",","."),"OSM ↗") | AK11: =HYPERLINK("https://www.google.com/maps/search/?api=1&query="&SUBSTITUTE(J11&"",",",".")&"%2C"&SUBSTITUTE(K11&"",",","."),"Google ↗") | AL11: =HYPERLINK(URL_TABLEAU&"#"&A11,"Dossier ↗")
A12: INC-2026-011 | B12: 46283 | C12: =WEEKNUM(B12,21) | D12: =IF(B12<P_DEBUT_P2,"P1","P2") | E12: Mali | F12: Koulikoro | G12: Kati | H12: Koulikoro | I12: Kassela (~40km Bamako) | J12: 12.5833 | K12: -7.7167 | L12: Localité | M12: Attaque de Poste / Infiltration | N12: Attaque de poste / camp | O12: JNIM | P12: JNIM | Q12: FAMa / Africa Corps | R12: Poste de contrôle FAMa | S12: Attaque nocturne (21h-22h) et prise de contrôle totale d'un poste de l'armée à seulement 40 km de Bamako. | T12: 0 | U12: 0 | V12: 3 | W12: 0 | X12: 0 | Y12: =T12+V12+W12+X12 | Z12: 0 | AA12: 1 | AB12: 0 | AC12: Armes légères et munitions | AD12: Poste de contrôle de Kassela incendié | AE12: =ROUND(2*6371*ASIN(SQRT(SIN(RADIANS(J12-LAT_BAMAKO)/2)^2+COS(RADIANS(LAT_BAMAKO))*COS(RADIANS(J12))*SIN(RADIANS(K12-LON_BAMAKO)/2)^2)),0) | AF12: =IF(AE12<=SEUIL_KM,"Oui","Non") | AG12: Partiellement corroboré | AH12: Non | AI12: Sahel Alerte, AzZalaqa, Naïm TOURÉ | AJ12: =HYPERLINK("https://www.openstreetmap.org/?mlat="&SUBSTITUTE(J12&"",",",".")&"&mlon="&SUBSTITUTE(K12&"",",",".")&"#map=11/"&SUBSTITUTE(J12&"",",",".")&"/"&SUBSTITUTE(K12&"",",","."),"OSM ↗") | AK12: =HYPERLINK("https://www.google.com/maps/search/?api=1&query="&SUBSTITUTE(J12&"",",",".")&"%2C"&SUBSTITUTE(K12&"",",","."),"Google ↗") | AL12: =HYPERLINK(URL_TABLEAU&"#"&A12,"Dossier ↗")
A13: INC-2026-012 | B13: 46284 | C13: =WEEKNUM(B13,21) | D13: =IF(B13<P_DEBUT_P2,"P1","P2") | E13: Mali | F13: Ségou | G13: Bla | H13: Ségou | I13: Bla & Noumouna | J13: 12.95 | K13: -5.75 | L13: Localité | M13: Attaque / Menace Sécuritaire | N13: Attaque de poste / camp | O13: JNIM | P13: JNIM | Q13: FAMa / Africa Corps | R13: FAMa / Positions administratives | S13: Pression sécuritaire accrue et attaques ciblées sur Noumouna et Bla. Entraîne l'annulation des cérémonies de l'indépendance à Bla. | T13: 0 | U13: 0 | V13: 0 | W13: 0 | X13: 0 | Y13: =T13+V13+W13+X13 | Z13: 0 | AA13: 0 | AB13: 0 | AC13: Non spécifié | AD13: Festivités nationales du 22 septembre annulées | AE13: =ROUND(2*6371*ASIN(SQRT(SIN(RADIANS(J13-LAT_BAMAKO)/2)^2+COS(RADIANS(LAT_BAMAKO))*COS(RADIANS(J13))*SIN(RADIANS(K13-LON_BAMAKO)/2)^2)),0) | AF13: =IF(AE13<=SEUIL_KM,"Oui","Non") | AG13: Partiellement corroboré | AH13: Non | AI13: Sahel Alerte, Naïm TOURÉ | AJ13: =HYPERLINK("https://www.openstreetmap.org/?mlat="&SUBSTITUTE(J13&"",",",".")&"&mlon="&SUBSTITUTE(K13&"",",",".")&"#map=11/"&SUBSTITUTE(J13&"",",",".")&"/"&SUBSTITUTE(K13&"",",","."),"OSM ↗") | AK13: =HYPERLINK("https://www.google.com/maps/search/?api=1&query="&SUBSTITUTE(J13&"",",",".")&"%2C"&SUBSTITUTE(K13&"",",","."),"Google ↗") | AL13: =HYPERLINK(URL_TABLEAU&"#"&A13,"Dossier ↗")
... A37: INC-2026-036 | B37: 46321 | C37: =WEEKNUM(B37,21) | D37: =IF(B37<P_DEBUT_P2,"P1","P2") | E37: Mali | F37: Ségou | G37: Niono | H37: Ségou | I37: Nampala | J37: 15.2833 | K37: -5.3167 | L37: Localité | M37: Attaque à l'EEI Dirigé | N37: EEI | O37: JNIM | P37: JNIM | Q37: FAMa / Africa Corps | R37: Poste FAMa à l'entrée de la ville | S37: Attaque ciblant un poste de contrôle à l'entrée de Nampala avec un engin explosif télécommandé. | T37: 0 | U37: 0 | V37: 2 | W37: 0 | X37: 0 | Y37: =T37+V37+W37+X37 | Z37: 0 | AA37: 1 | AB37: 0 | AC37: Aucun | AD37: Poste de contrôle endommagé | AE37: =ROUND(2*6371*ASIN(SQRT(SIN(RADIANS(J37-LAT_BAMAKO)/2)^2+COS(RADIANS(LAT_BAMAKO))*COS(RADIANS(J37))*SIN(RADIANS(K37-LON_BAMAKO)/2)^2)),0) | AF37: =IF(AE37<=SEUIL_KM,"Oui","Non") | AG37: Partiellement corroboré | AH37: Non | AI37: AzZalaqa, Sahel Alerte, Naïm TOURÉ | AJ37: =HYPERLINK("https://www.openstreetmap.org/?mlat="&SUBSTITUTE(J37&"",",",".")&"&mlon="&SUBSTITUTE(K37&"",",",".")&"#map=11/"&SUBSTITUTE(J37&"",",",".")&"/"&SUBSTITUTE(K37&"",",","."),"OSM ↗") | AK37: =HYPERLINK("https://www.google.com/maps/search/?api=1&query="&SUBSTITUTE(J37&"",",",".")&"%2C"&SUBSTITUTE(K37&"",",","."),"Google ↗") | AL37: =HYPERLINK(URL_TABLEAU&"#"&A37,"Dossier ↗")

Sheet REGIONS
A1: Synthèse régionale et indice de menace | P1: ◄ Accueil
A2: Toutes les valeurs sont calculées par formule à partir de la feuille INCIDENTS.
B4: Région | C4: Incidents | D4: Part | E4: Tués | F4: FDS + Africa Corps tués | G4: Civils tués + blessés | H4: Incidents récents | I4: Indice (0-100) | J4: Niveau | K4: Acteur dominant | L4: JNIM | M4: EI-Sahel | N4: FLA | O4: FAMa / Africa Corps | P4: Indéterminé / accident
B5: Ségou | C5: =COUNTIFS(inc_region,$B5) | D5: =IF(SUM($C$5:$C$12)=0,0,C5/SUM($C$5:$C$12)) | E5: =SUMIFS(inc_tues,inc_region,$B5) | F5: =SUMIFS(inc_fama,inc_region,$B5)+SUMIFS(inc_ac,inc_region,$B5) | G5: =SUMIFS(inc_civ_k,inc_region,$B5)+SUMIFS(inc_civ_w,inc_region,$B5) | H5: =COUNTIFS(inc_region,$B5,inc_date,">="&(P_FIN-FEN_RECENTE+1)) | I5: =IF(C5=0,0,ROUND(100*(W_FREQ*C5/MAX($C$5:$C$12)+W_LETAL*LN(1+E5)/LN(1+MAX(1,MAX($E$5:$E$12)))+W_CIVILS*IF(MAX($G$5:$G$12)=0,0,G5/MAX($G$5:$G$12))+W_RECENT*H5/C5),0)) | J5: =IF(I5>=S_CRITIQUE,"Critique",IF(I5>=S_ELEVE,"Élevé",IF(I5>=S_MODERE,"Modéré","Faible"))) | K5: =IF(C5=0,"—",INDEX($L$4:$P$4,MATCH(MAX(L5:P5),L5:P5,0))) | L5: =COUNTIFS(inc_region,$B5,inc_acteur,L$4) | M5: =COUNTIFS(inc_region,$B5,inc_acteur,M$4) | N5: =COUNTIFS(inc_region,$B5,inc_acteur,N$4) | O5: =COUNTIFS(inc_region,$B5,inc_acteur,O$4) | P5: =COUNTIFS(inc_region,$B5,inc_acteur,P$4)
B6: Mopti | C6: =COUNTIFS(inc_region,$B6) | D6: =IF(SUM($C$5:$C$12)=0,0,C6/SUM($C$5:$C$12)) | E6: =SUMIFS(inc_tues,inc_region,$B6) | F6: =SUMIFS(inc_fama,inc_region,$B6)+SUMIFS(inc_ac,inc_region,$B6) | G6: =SUMIFS(inc_civ_k,inc_region,$B6)+SUMIFS(inc_civ_w,inc_region,$B6) | H6: =COUNTIFS(inc_region,$B6,inc_date,">="&(P_FIN-FEN_RECENTE+1)) | I6: =IF(C6=0,0,ROUND(100*(W_FREQ*C6/MAX($C$5:$C$12)+W_LETAL*LN(1+E6)/LN(1+MAX(1,MAX($E$5:$E$12)))+W_CIVILS*IF(MAX($G$5:$G$12)=0,0,G6/MAX($G$5:$G$12))+W_RECENT*H6/C6),0)) | J6: =IF(I6>=S_CRITIQUE,"Critique",IF(I6>=S_ELEVE,"Élevé",IF(I6>=S_MODERE,"Modéré","Faible"))) | K6: =IF(C6=0,"—",INDEX($L$4:$P$4,MATCH(MAX(L6:P6),L6:P6,0))) | L6: =COUNTIFS(inc_region,$B6,inc_acteur,L$4) | M6: =COUNTIFS(inc_region,$B6,inc_acteur,M$4) | N6: =COUNTIFS(inc_region,$B6,inc_acteur,N$4) | O6: =COUNTIFS(inc_region,$B6,inc_acteur,O$4) | P6: =COUNTIFS(inc_region,$B6,inc_acteur,P$4)
B7: Kidal | C7: =COUNTIFS(inc_region,$B7) | D7: =IF(SUM($C$5:$C$12)=0,0,C7/SUM($C$5:$C$12)) | E7: =SUMIFS(inc_tues,inc_region,$B7) | F7: =SUMIFS(inc_fama,inc_region,$B7)+SUMIFS(inc_ac,inc_region,$B7) | G7: =SUMIFS(inc_civ_k,inc_region,$B7)+SUMIFS(inc_civ_w,inc_region,$B7) | H7: =COUNTIFS(inc_region,$B7,inc_date,">="&(P_FIN-FEN_RECENTE+1)) | I7: =IF(C7=0,0,ROUND(100*(W_FREQ*C7/MAX($C$5:$C$12)+W_LETAL*LN(1+E7)/LN(1+MAX(1,MAX($E$5:$E$12)))+W_CIVILS*IF(MAX($G$5:$G$12)=0,0,G7/MAX($G$5:$G$12))+W_RECENT*H7/C7),0)) | J7: =IF(I7>=S_CRITIQUE,"Critique",IF(I7>=S_ELEVE,"Élevé",IF(I7>=S_MODERE,"Modéré","Faible"))) | K7: =IF(C7=0,"—",INDEX($L$4:$P$4,MATCH(MAX(L7:P7),L7:P7,0))) | L7: =COUNTIFS(inc_region,$B7,inc_acteur,L$4) | M7: =COUNTIFS(inc_region,$B7,inc_acteur,M$4) | N7: =COUNTIFS(inc_region,$B7,inc_acteur,N$4) | O7: =COUNTIFS(inc_region,$B7,inc_acteur,O$4) | P7: =COUNTIFS(inc_region,$B7,inc_acteur,P$4)
B8: Tombouctou | C8: =COUNTIFS(inc_region,$B8) | D8: =IF(SUM($C$5:$C$12)=0,0,C8/SUM($C$5:$C$12)) | E8: =SUMIFS(inc_tues,inc_region,$B8) | F8: =SUMIFS(inc_fama,inc_region,$B8)+SUMIFS(inc_ac,inc_region,$B8) | G8: =SUMIFS(inc_civ_k,inc_region,$B8)+SUMIFS(inc_civ_w,inc_region,$B8) | H8: =COUNTIFS(inc_region,$B8,inc_date,">="&(P_FIN-FEN_RECENTE+1)) | I8: =IF(C8=0,0,ROUND(100*(W_FREQ*C8/MAX($C$5:$C$12)+W_LETAL*LN(1+E8)/LN(1+MAX(1,MAX($E$5:$E$12)))+W_CIVILS*IF(MAX($G$5:$G$12)=0,0,G8/MAX($G$5:$G$12))+W_RECENT*H8/C8),0)) | J8: =IF(I8>=S_CRITIQUE,"Critique",IF(I8>=S_ELEVE,"Élevé",IF(I8>=S_MODERE,"Modéré","Faible"))) | K8: =IF(C8=0,"—",INDEX($L$4:$P$4,MATCH(MAX(L8:P8),L8:P8,0))) | L8: =COUNTIFS(inc_region,$B8,inc_acteur,L$4) | M8: =COUNTIFS(inc_region,$B8,inc_acteur,M$4) | N8: =COUNTIFS(inc_region,$B8,inc_acteur,N$4) | O8: =COUNTIFS(inc_region,$B8,inc_acteur,O$4) | P8: =COUNTIFS(inc_region,$B8,inc_acteur,P$4)
B9: Gao | C9: =COUNTIFS(inc_region,$B9) | D9: =IF(SUM($C$5:$C$12)=0,0,C9/SUM($C$5:$C$12)) | E9: =SUMIFS(inc_tues,inc_region,$B9) | F9: =SUMIFS(inc_fama,inc_region,$B9)+SUMIFS(inc_ac,inc_region,$B9) | G9: =SUMIFS(inc_civ_k,inc_region,$B9)+SUMIFS(inc_civ_w,inc_region,$B9) | H9: =COUNTIFS(inc_region,$B9,inc_date,">="&(P_FIN-FEN_RECENTE+1)) | I9: =IF(C9=0,0,ROUND(100*(W_FREQ*C9/MAX($C$5:$C$12)+W_LETAL*LN(1+E9)/LN(1+MAX(1,MAX($E$5:$E$12)))+W_CIVILS*IF(MAX($G$5:$G$12)=0,0,G9/MAX($G$5:$G$12))+W_RECENT*H9/C9),0)) | J9: =IF(I9>=S_CRITIQUE,"Critique",IF(I9>=S_ELEVE,"Élevé",IF(I9>=S_MODERE,"Modéré","Faible"))) | K9: =IF(C9=0,"—",INDEX($L$4:$P$4,MATCH(MAX(L9:P9),L9:P9,0))) | L9: =COUNTIFS(inc_region,$B9,inc_acteur,L$4) | M9: =COUNTIFS(inc_region,$B9,inc_acteur,M$4) | N9: =COUNTIFS(inc_region,$B9,inc_acteur,N$4) | O9: =COUNTIFS(inc_region,$B9,inc_acteur,O$4) | P9: =COUNTIFS(inc_region,$B9,inc_acteur,P$4)
B10: Koulikoro | C10: =COUNTIFS(inc_region,$B10) | D10: =IF(SUM($C$5:$C$12)=0,0,C10/SUM($C$5:$C$12)) | E10: =SUMIFS(inc_tues,inc_region,$B10) | F10: =SUMIFS(inc_fama,inc_region,$B10)+SUMIFS(inc_ac,inc_region,$B10) | G10: =SUMIFS(inc_civ_k,inc_region,$B10)+SUMIFS(inc_civ_w,inc_region,$B10) | H10: =COUNTIFS(inc_region,$B10,inc_date,">="&(P_FIN-FEN_RECENTE+1)) | I10: =IF(C10=0,0,ROUND(100*(W_FREQ*C10/MAX($C$5:$C$12)+W_LETAL*LN(1+E10)/LN(1+MAX(1,MAX($E$5:$E$12)))+W_CIVILS*IF(MAX($G$5:$G$12)=0,0,G10/MAX($G$5:$G$12))+W_RECENT*H10/C10),0)) | J10: =IF(I10>=S_CRITIQUE,"Critique",IF(I10>=S_ELEVE,"Élevé",IF(I10>=S_MODERE,"Modéré","Faible"))) | K10: =IF(C10=0,"—",INDEX($L$4:$P$4,MATCH(MAX(L10:P10),L10:P10,0))) | L10: =COUNTIFS(inc_region,$B10,inc_acteur,L$4) | M10: =COUNTIFS(inc_region,$B10,inc_acteur,M$4) | N10: =COUNTIFS(inc_region,$B10,inc_acteur,N$4) | O10: =COUNTIFS(inc_region,$B10,inc_acteur,O$4) | P10: =COUNTIFS(inc_region,$B10,inc_acteur,P$4)
B11: Sikasso | C11: =COUNTIFS(inc_region,$B11) | D11: =IF(SUM($C$5:$C$12)=0,0,C11/SUM($C$5:$C$12)) | E11: =SUMIFS(inc_tues,inc_region,$B11) | F11: =SUMIFS(inc_fama,inc_region,$B11)+SUMIFS(inc_ac,inc_region,$B11) | G11: =SUMIFS(inc_civ_k,inc_region,$B11)+SUMIFS(inc_civ_w,inc_region,$B11) | H11: =COUNTIFS(inc_region,$B11,inc_date,">="&(P_FIN-FEN_RECENTE+1)) | I11: =IF(C11=0,0,ROUND(100*(W_FREQ*C11/MAX($C$5:$C$12)+W_LETAL*LN(1+E11)/LN(1+MAX(1,MAX($E$5:$E$12)))+W_CIVILS*IF(MAX($G$5:$G$12)=0,0,G11/MAX($G$5:$G$12))+W_RECENT*H11/C11),0)) | J11: =IF(I11>=S_CRITIQUE,"Critique",IF(I11>=S_ELEVE,"Élevé",IF(I11>=S_MODERE,"Modéré","Faible"))) | K11: =IF(C11=0,"—",INDEX($L$4:$P$4,MATCH(MAX(L11:P11),L11:P11,0))) | L11: =COUNTIFS(inc_region,$B11,inc_acteur,L$4) | M11: =COUNTIFS(inc_region,$B11,inc_acteur,M$4) | N11: =COUNTIFS(inc_region,$B11,inc_acteur,N$4) | O11: =COUNTIFS(inc_region,$B11,inc_acteur,O$4) | P11: =COUNTIFS(inc_region,$B11,inc_acteur,P$4)
B12: Hors Mali (Burkina Faso) | C12: =COUNTIFS(inc_region,$B12) | D12: =IF(SUM($C$5:$C$12)=0,0,C12/SUM($C$5:$C$12)) | E12: =SUMIFS(inc_tues,inc_region,$B12) | F12: =SUMIFS(inc_fama,inc_region,$B12)+SUMIFS(inc_ac,inc_region,$B12) | G12: =SUMIFS(inc_civ_k,inc_region,$B12)+SUMIFS(inc_civ_w,inc_region,$B12) | H12: =COUNTIFS(inc_region,$B12,inc_date,">="&(P_FIN-FEN_RECENTE+1)) | I12: =IF(C12=0,0,ROUND(100*(W_FREQ*C12/MAX($C$5:$C$12)+W_LETAL*LN(1+E12)/LN(1+MAX(1,MAX($E$5:$E$12)))+W_CIVILS*IF(MAX($G$5:$G$12)=0,0,G12/MAX($G$5:$G$12))+W_RECENT*H12/C12),0)) | J12: =IF(I12>=S_CRITIQUE,"Critique",IF(I12>=S_ELEVE,"Élevé",IF(I12>=S_MODERE,"Modéré","Faible"))) | K12: =IF(C12=0,"—",INDEX($L$4:$P$4,MATCH(MAX(L12:P12),L12:P12,0))) | L12: =COUNTIFS(inc_region,$B12,inc_acteur,L$4) | M12: =COUNTIFS(inc_region,$B12,inc_acteur,M$4) | N12: =COUNTIFS(inc_region,$B12,inc_acteur,N$4) | O12: =COUNTIFS(inc_region,$B12,inc_acteur,O$4) | P12: =COUNTIFS(inc_region,$B12,inc_acteur,P$4)
B13: Total | C13: =SUM(C5:C12) | D13: =SUM(D5:D12) | E13: =SUM(E5:E12) | F13: =SUM(F5:F12) | G13: =SUM(G5:G12) | H13: =SUM(H5:H12) | L13: =SUM(L5:L12) | M13: =SUM(M5:M12) | N13: =SUM(N5:N12) | O13: =SUM(O5:O12) | P13: =SUM(P5:P12)
B15: Méthode : indice = 100 × (W_FREQ × incidents / max + W_LETAL × ln(1+tués) / ln(1+max) + W_CIVILS × civils / max + W_RECENT × part d'incidents récents). Poids et seuils modifiables dans PARAMETRES. Les régions suivent le référentiel geoBoundaries (8 régions + Bamako, antérieur à la réforme de 2023).

Sheet ACTEURS
A1: Synthèse par acteur instigateur | O1: ◄ Accueil
A2: « Tués lors de ses actions » inclut les pertes subies par l'acteur lui-même lors des incidents qu'il initie.
B4: Acteur | C4: Incidents | D4: Part | E4: Tués lors de ses actions | F4: FDS (FAMa) tués | G4: Africa Corps tués | H4: Civils tués | I4: Civils blessés | J4: Combattants armés tués | K4: Capturés | L4: Véh. détruits | M4: Véh. saisis | N4: Incidents P1 | O4: Incidents P2 | P4: Évolution P1 → P2
B5: JNIM | C5: =COUNTIFS(inc_acteur,$B5) | D5: =IF(SUM($C$5:$C$9)=0,0,C5/SUM($C$5:$C$9)) | E5: =SUMIFS(inc_tues,inc_acteur,$B5) | F5: =SUMIFS(inc_fama,inc_acteur,$B5) | G5: =SUMIFS(inc_ac,inc_acteur,$B5) | H5: =SUMIFS(inc_civ_k,inc_acteur,$B5) | I5: =SUMIFS(inc_civ_w,inc_acteur,$B5) | J5: =SUMIFS(inc_ga,inc_acteur,$B5) | K5: =SUMIFS(inc_pow,inc_acteur,$B5) | L5: =SUMIFS(inc_vehd,inc_acteur,$B5) | M5: =SUMIFS(inc_vehs,inc_acteur,$B5) | N5: =COUNTIFS(inc_acteur,$B5,inc_periode,"P1") | O5: =COUNTIFS(inc_acteur,$B5,inc_periode,"P2") | P5: =IF(N5=0,IF(O5=0,"—","nouveau"),(O5-N5)/N5)
B6: EI-Sahel | C6: =COUNTIFS(inc_acteur,$B6) | D6: =IF(SUM($C$5:$C$9)=0,0,C6/SUM($C$5:$C$9)) | E6: =SUMIFS(inc_tues,inc_acteur,$B6) | F6: =SUMIFS(inc_fama,inc_acteur,$B6) | G6: =SUMIFS(inc_ac,inc_acteur,$B6) | H6: =SUMIFS(inc_civ_k,inc_acteur,$B6) | I6: =SUMIFS(inc_civ_w,inc_acteur,$B6) | J6: =SUMIFS(inc_ga,inc_acteur,$B6) | K6: =SUMIFS(inc_pow,inc_acteur,$B6) | L6: =SUMIFS(inc_vehd,inc_acteur,$B6) | M6: =SUMIFS(inc_vehs,inc_acteur,$B6) | N6: =COUNTIFS(inc_acteur,$B6,inc_periode,"P1") | O6: =COUNTIFS(inc_acteur,$B6,inc_periode,"P2") | P6: =IF(N6=0,IF(O6=0,"—","nouveau"),(O6-N6)/N6)
B7: FLA | C7: =COUNTIFS(inc_acteur,$B7) | D7: =IF(SUM($C$5:$C$9)=0,0,C7/SUM($C$5:$C$9)) | E7: =SUMIFS(inc_tues,inc_acteur,$B7) | F7: =SUMIFS(inc_fama,inc_acteur,$B7) | G7: =SUMIFS(inc_ac,inc_acteur,$B7) | H7: =SUMIFS(inc_civ_k,inc_acteur,$B7) | I7: =SUMIFS(inc_civ_w,inc_acteur,$B7) | J7: =SUMIFS(inc_ga,inc_acteur,$B7) | K7: =SUMIFS(inc_pow,inc_acteur,$B7) | L7: =SUMIFS(inc_vehd,inc_acteur,$B7) | M7: =SUMIFS(inc_vehs,inc_acteur,$B7) | N7: =COUNTIFS(inc_acteur,$B7,inc_periode,"P1") | O7: =COUNTIFS(inc_acteur,$B7,inc_periode,"P2") | P7: =IF(N7=0,IF(O7=0,"—","nouveau"),(O7-N7)/N7)
B8: FAMa / Africa Corps | C8: =COUNTIFS(inc_acteur,$B8) | D8: =IF(SUM($C$5:$C$9)=0,0,C8/SUM($C$5:$C$9)) | E8: =SUMIFS(inc_tues,inc_acteur,$B8) | F8: =SUMIFS(inc_fama,inc_acteur,$B8) | G8: =SUMIFS(inc_ac,inc_acteur,$B8) | H8: =SUMIFS(inc_civ_k,inc_acteur,$B8) | I8: =SUMIFS(inc_civ_w,inc_acteur,$B8) | J8: =SUMIFS(inc_ga,inc_acteur,$B8) | K8: =SUMIFS(inc_pow,inc_acteur,$B8) | L8: =SUMIFS(inc_vehd,inc_acteur,$B8) | M8: =SUMIFS(inc_vehs,inc_acteur,$B8) | N8: =COUNTIFS(inc_acteur,$B8,inc_periode,"P1") | O8: =COUNTIFS(inc_acteur,$B8,inc_periode,"P2") | P8: =IF(N8=0,IF(O8=0,"—","nouveau"),(O8-N8)/N8)
B9: Indéterminé / accident | C9: =COUNTIFS(inc_acteur,$B9) | D9: =IF(SUM($C$5:$C$9)=0,0,C9/SUM($C$5:$C$9)) | E9: =SUMIFS(inc_tues,inc_acteur,$B9) | F9: =SUMIFS(inc_fama,inc_acteur,$B9) | G9: =SUMIFS(inc_ac,inc_acteur,$B9) | H9: =SUMIFS(inc_civ_k,inc_acteur,$B9) | I9: =SUMIFS(inc_civ_w,inc_acteur,$B9) | J9: =SUMIFS(inc_ga,inc_acteur,$B9) | K9: =SUMIFS(inc_pow,inc_acteur,$B9) | L9: =SUMIFS(inc_vehd,inc_acteur,$B9) | M9: =SUMIFS(inc_vehs,inc_acteur,$B9) | N9: =COUNTIFS(inc_acteur,$B9,inc_periode,"P1") | O9: =COUNTIFS(inc_acteur,$B9,inc_periode,"P2") | P9: =IF(N9=0,IF(O9=0,"—","nouveau"),(O9-N9)/N9)
B10: Total | C10: =SUM(C5:C9) | D10: =SUM(D5:D9) | E10: =SUM(E5:E9) | F10: =SUM(F5:F9) | G10: =SUM(G5:G9) | H10: =SUM(H5:H9) | I10: =SUM(I5:I9) | J10: =SUM(J5:J9) | ... O10: =SUM(O5:O9) | P10: =IF(N10=0,"—",(O10-N10)/N10)
B12: Matrice acteur × mode opératoire (nombre d'incidents)
B13: Acteur | C13: Affrontement JNIM–EIS | D13: Attaque ciblée / VIP | E13: Attaque de poste / camp | F13: Drone armé (FPV) | G13: EEI | H13: Embuscade | I13: Frappe aérienne étatique | J13: Lutte anti-drone | K13: Offensive terrestre | L13: Perte d'aéronef (accident) | M13: Sabotage logistique | N13: Tirs indirects | O13: Total
B14: JNIM | C14: =COUNTIFS(inc_acteur,$B14,inc_mode,C$13) | D14: =COUNTIFS(inc_acteur,$B14,inc_mode,D$13) | E14: =COUNTIFS(inc_acteur,$B14,inc_mode,E$13) | F14: =COUNTIFS(inc_acteur,$B14,inc_mode,F$13) | G14: =COUNTIFS(inc_acteur,$B14,inc_mode,G$13) | H14: =COUNTIFS(inc_acteur,$B14,inc_mode,H$13) | I14: =COUNTIFS(inc_acteur,$B14,inc_mode,I$13) | J14: =COUNTIFS(inc_acteur,$B14,inc_mode,J$13) | ... N14: =COUNTIFS(inc_acteur,$B14,inc_mode,N$13) | O14: =SUM(C14:N14)
B15: EI-Sahel | C15: =COUNTIFS(inc_acteur,$B15,inc_mode,C$13) | D15: =COUNTIFS(inc_acteur,$B15,inc_mode,D$13) | E15: =COUNTIFS(inc_acteur,$B15,inc_mode,E$13) | F15: =COUNTIFS(inc_acteur,$B15,inc_mode,F$13) | G15: =COUNTIFS(inc_acteur,$B15,inc_mode,G$13) | H15: =COUNTIFS(inc_acteur,$B15,inc_mode,H$13) | I15: =COUNTIFS(inc_acteur,$B15,inc_mode,I$13) | J15: =COUNTIFS(inc_acteur,$B15,inc_mode,J$13) | ... N15: =COUNTIFS(inc_acteur,$B15,inc_mode,N$13) | O15: =SUM(C15:N15)
B16: FLA | C16: =COUNTIFS(inc_acteur,$B16,inc_mode,C$13) | D16: =COUNTIFS(inc_acteur,$B16,inc_mode,D$13) | E16: =COUNTIFS(inc_acteur,$B16,inc_mode,E$13) | F16: =COUNTIFS(inc_acteur,$B16,inc_mode,F$13) | G16: =COUNTIFS(inc_acteur,$B16,inc_mode,G$13) | H16: =COUNTIFS(inc_acteur,$B16,inc_mode,H$13) | I16: =COUNTIFS(inc_acteur,$B16,inc_mode,I$13) | J16: =COUNTIFS(inc_acteur,$B16,inc_mode,J$13) | ... N16: =COUNTIFS(inc_acteur,$B16,inc_mode,N$13) | O16: =SUM(C16:N16)
B17: FAMa / Africa Corps | C17: =COUNTIFS(inc_acteur,$B17,inc_mode,C$13) | D17: =COUNTIFS(inc_acteur,$B17,inc_mode,D$13) | E17: =COUNTIFS(inc_acteur,$B17,inc_mode,E$13) | F17: =COUNTIFS(inc_acteur,$B17,inc_mode,F$13) | G17: =COUNTIFS(inc_acteur,$B17,inc_mode,G$13) | H17: =COUNTIFS(inc_acteur,$B17,inc_mode,H$13) | I17: =COUNTIFS(inc_acteur,$B17,inc_mode,I$13) | J17: =COUNTIFS(inc_acteur,$B17,inc_mode,J$13) | ... N17: =COUNTIFS(inc_acteur,$B17,inc_mode,N$13) | O17: =SUM(C17:N17)
B18: Indéterminé / accident | C18: =COUNTIFS(inc_acteur,$B18,inc_mode,C$13) | D18: =COUNTIFS(inc_acteur,$B18,inc_mode,D$13) | E18: =COUNTIFS(inc_acteur,$B18,inc_mode,E$13) | F18: =COUNTIFS(inc_acteur,$B18,inc_mode,F$13) | G18: =COUNTIFS(inc_acteur,$B18,inc_mode,G$13) | H18: =COUNTIFS(inc_acteur,$B18,inc_mode,H$13) | I18: =COUNTIFS(inc_acteur,$B18,inc_mode,I$13) | J18: =COUNTIFS(inc_acteur,$B18,inc_mode,J$13) | ... N18: =COUNTIFS(inc_acteur,$B18,inc_mode,N$13) | O18: =SUM(C18:N18)

Sheet CHRONOLOGIE
A1: Chronologie et comparaison des périodes | O1: ◄ Accueil
A2: Semaines ISO (lundi → dimanche). P1 / P2 : deux périodes de durée égale (voir PARAMETRES).
B4: Semaine du | C4: Au | D4: N° ISO | E4: JNIM | F4: EI-Sahel | G4: FLA | H4: FAMa / Africa Corps | I4: Indéterminé / accident | J4: Total incidents | K4: Tués | L4: FDS + AC tués | M4: Civils tués | N4: Cumul tués | Q4: Comparaison P1 / P2
B5: 46265 | C5: =B5+6 | D5: ="S"&WEEKNUM(B5,21) | E5: =COUNTIFS(inc_acteur,E$4,inc_date,">="&$B5,inc_date,"<="&$C5) | F5: =COUNTIFS(inc_acteur,F$4,inc_date,">="&$B5,inc_date,"<="&$C5) | G5: =COUNTIFS(inc_acteur,G$4,inc_date,">="&$B5,inc_date,"<="&$C5) | H5: =COUNTIFS(inc_acteur,H$4,inc_date,">="&$B5,inc_date,"<="&$C5) | I5: =COUNTIFS(inc_acteur,I$4,inc_date,">="&$B5,inc_date,"<="&$C5) | J5: =SUM(E5:I5) | K5: =SUMIFS(inc_tues,inc_date,">="&$B5,inc_date,"<="&$C5) | L5: =SUMIFS(inc_fama,inc_date,">="&$B5,inc_date,"<="&$C5)+SUMIFS(inc_ac,inc_date,">="&$B5,inc_date,"<="&$C5) | M5: =SUMIFS(inc_civ_k,inc_date,">="&$B5,inc_date,"<="&$C5) | N5: =SUM($K$5:K5) | Q5: Indicateur | R5: P1 | S5: P2 | T5: Écart | U5: Évolution
B6: 46272 | C6: =B6+6 | D6: ="S"&WEEKNUM(B6,21) | E6: =COUNTIFS(inc_acteur,E$4,inc_date,">="&$B6,inc_date,"<="&$C6) | F6: =COUNTIFS(inc_acteur,F$4,inc_date,">="&$B6,inc_date,"<="&$C6) | G6: =COUNTIFS(inc_acteur,G$4,inc_date,">="&$B6,inc_date,"<="&$C6) | H6: =COUNTIFS(inc_acteur,H$4,inc_date,">="&$B6,inc_date,"<="&$C6) | I6: =COUNTIFS(inc_acteur,I$4,inc_date,">="&$B6,inc_date,"<="&$C6) | J6: =SUM(E6:I6) | K6: =SUMIFS(inc_tues,inc_date,">="&$B6,inc_date,"<="&$C6) | L6: =SUMIFS(inc_fama,inc_date,">="&$B6,inc_date,"<="&$C6)+SUMIFS(inc_ac,inc_date,">="&$B6,inc_date,"<="&$C6) | M6: =SUMIFS(inc_civ_k,inc_date,">="&$B6,inc_date,"<="&$C6) | N6: =SUM($K$5:K6) | Q6: Incidents | R6: =COUNTIFS(inc_periode,"P1") | S6: =COUNTIFS(inc_periode,"P2") | T6: =S6-R6 | U6: =IF(R6=0,"—",(S6-R6)/R6)
B7: 46279 | C7: =B7+6 | D7: ="S"&WEEKNUM(B7,21) | E7: =COUNTIFS(inc_acteur,E$4,inc_date,">="&$B7,inc_date,"<="&$C7) | F7: =COUNTIFS(inc_acteur,F$4,inc_date,">="&$B7,inc_date,"<="&$C7) | G7: =COUNTIFS(inc_acteur,G$4,inc_date,">="&$B7,inc_date,"<="&$C7) | H7: =COUNTIFS(inc_acteur,H$4,inc_date,">="&$B7,inc_date,"<="&$C7) | I7: =COUNTIFS(inc_acteur,I$4,inc_date,">="&$B7,inc_date,"<="&$C7) | J7: =SUM(E7:I7) | K7: =SUMIFS(inc_tues,inc_date,">="&$B7,inc_date,"<="&$C7) | L7: =SUMIFS(inc_fama,inc_date,">="&$B7,inc_date,"<="&$C7)+SUMIFS(inc_ac,inc_date,">="&$B7,inc_date,"<="&$C7) | M7: =SUMIFS(inc_civ_k,inc_date,">="&$B7,inc_date,"<="&$C7) | N7: =SUM($K$5:K7) | Q7: Tués (total) | R7: =SUMIFS(inc_tues,inc_periode,"P1") | S7: =SUMIFS(inc_tues,inc_periode,"P2") | T7: =S7-R7 | U7: =IF(R7=0,"—",(S7-R7)/R7)
B8: 46286 | C8: =B8+6 | D8: ="S"&WEEKNUM(B8,21) | E8: =COUNTIFS(inc_acteur,E$4,inc_date,">="&$B8,inc_date,"<="&$C8) | F8: =COUNTIFS(inc_acteur,F$4,inc_date,">="&$B8,inc_date,"<="&$C8) | G8: =COUNTIFS(inc_acteur,G$4,inc_date,">="&$B8,inc_date,"<="&$C8) | H8: =COUNTIFS(inc_acteur,H$4,inc_date,">="&$B8,inc_date,"<="&$C8) | I8: =COUNTIFS(inc_acteur,I$4,inc_date,">="&$B8,inc_date,"<="&$C8) | J8: =SUM(E8:I8) | K8: =SUMIFS(inc_tues,inc_date,">="&$B8,inc_date,"<="&$C8) | L8: =SUMIFS(inc_fama,inc_date,">="&$B8,inc_date,"<="&$C8)+SUMIFS(inc_ac,inc_date,">="&$B8,inc_date,"<="&$C8) | M8: =SUMIFS(inc_civ_k,inc_date,">="&$B8,inc_date,"<="&$C8) | N8: =SUM($K$5:K8) | Q8: FDS (FAMa) tués | R8: =SUMIFS(inc_fama,inc_periode,"P1") | S8: =SUMIFS(inc_fama,inc_periode,"P2") | T8: =S8-R8 | U8: =IF(R8=0,"—",(S8-R8)/R8)
B9: 46293 | C9: =B9+6 | D9: ="S"&WEEKNUM(B9,21) | E9: =COUNTIFS(inc_acteur,E$4,inc_date,">="&$B9,inc_date,"<="&$C9) | F9: =COUNTIFS(inc_acteur,F$4,inc_date,">="&$B9,inc_date,"<="&$C9) | G9: =COUNTIFS(inc_acteur,G$4,inc_date,">="&$B9,inc_date,"<="&$C9) | H9: =COUNTIFS(inc_acteur,H$4,inc_date,">="&$B9,inc_date,"<="&$C9) | I9: =COUNTIFS(inc_acteur,I$4,inc_date,">="&$B9,inc_date,"<="&$C9) | J9: =SUM(E9:I9) | K9: =SUMIFS(inc_tues,inc_date,">="&$B9,inc_date,"<="&$C9) | L9: =SUMIFS(inc_fama,inc_date,">="&$B9,inc_date,"<="&$C9)+SUMIFS(inc_ac,inc_date,">="&$B9,inc_date,"<="&$C9) | M9: =SUMIFS(inc_civ_k,inc_date,">="&$B9,inc_date,"<="&$C9) | N9: =SUM($K$5:K9) | Q9: Africa Corps tués | R9: =SUMIFS(inc_ac,inc_periode,"P1") | S9: =SUMIFS(inc_ac,inc_periode,"P2") | T9: =S9-R9 | U9: =IF(R9=0,"—",(S9-R9)/R9)
B10: 46300 | C10: =B10+6 | D10: ="S"&WEEKNUM(B10,21) | E10: =COUNTIFS(inc_acteur,E$4,inc_date,">="&$B10,inc_date,"<="&$C10) | F10: =COUNTIFS(inc_acteur,F$4,inc_date,">="&$B10,inc_date,"<="&$C10) | G10: =COUNTIFS(inc_acteur,G$4,inc_date,">="&$B10,inc_date,"<="&$C10) | H10: =COUNTIFS(inc_acteur,H$4,inc_date,">="&$B10,inc_date,"<="&$C10) | I10: =COUNTIFS(inc_acteur,I$4,inc_date,">="&$B10,inc_date,"<="&$C10) | J10: =SUM(E10:I10) | K10: =SUMIFS(inc_tues,inc_date,">="&$B10,inc_date,"<="&$C10) | L10: =SUMIFS(inc_fama,inc_date,">="&$B10,inc_date,"<="&$C10)+SUMIFS(inc_ac,inc_date,">="&$B10,inc_date,"<="&$C10) | M10: =SUMIFS(inc_civ_k,inc_date,">="&$B10,inc_date,"<="&$C10) | N10: =SUM($K$5:K10) | Q10: Combattants armés tués | R10: =SUMIFS(inc_ga,inc_periode,"P1") | S10: =SUMIFS(inc_ga,inc_periode,"P2") | T10: =S10-R10 | U10: =IF(R10=0,"—",(S10-R10)/R10)
B11: 46307 | C11: =B11+6 | D11: ="S"&WEEKNUM(B11,21) | E11: =COUNTIFS(inc_acteur,E$4,inc_date,">="&$B11,inc_date,"<="&$C11) | F11: =COUNTIFS(inc_acteur,F$4,inc_date,">="&$B11,inc_date,"<="&$C11) | G11: =COUNTIFS(inc_acteur,G$4,inc_date,">="&$B11,inc_date,"<="&$C11) | H11: =COUNTIFS(inc_acteur,H$4,inc_date,">="&$B11,inc_date,"<="&$C11) | I11: =COUNTIFS(inc_acteur,I$4,inc_date,">="&$B11,inc_date,"<="&$C11) | J11: =SUM(E11:I11) | K11: =SUMIFS(inc_tues,inc_date,">="&$B11,inc_date,"<="&$C11) | L11: =SUMIFS(inc_fama,inc_date,">="&$B11,inc_date,"<="&$C11)+SUMIFS(inc_ac,inc_date,">="&$B11,inc_date,"<="&$C11) | M11: =SUMIFS(inc_civ_k,inc_date,">="&$B11,inc_date,"<="&$C11) | N11: =SUM($K$5:K11) | Q11: Civils tués | R11: =SUMIFS(inc_civ_k,inc_periode,"P1") | S11: =SUMIFS(inc_civ_k,inc_periode,"P2") | T11: =S11-R11 | U11: =IF(R11=0,"—",(S11-R11)/R11)
B12: 46314 | C12: =B12+6 | D12: ="S"&WEEKNUM(B12,21) | E12: =COUNTIFS(inc_acteur,E$4,inc_date,">="&$B12,inc_date,"<="&$C12) | F12: =COUNTIFS(inc_acteur,F$4,inc_date,">="&$B12,inc_date,"<="&$C12) | G12: =COUNTIFS(inc_acteur,G$4,inc_date,">="&$B12,inc_date,"<="&$C12) | H12: =COUNTIFS(inc_acteur,H$4,inc_date,">="&$B12,inc_date,"<="&$C12) | I12: =COUNTIFS(inc_acteur,I$4,inc_date,">="&$B12,inc_date,"<="&$C12) | J12: =SUM(E12:I12) | K12: =SUMIFS(inc_tues,inc_date,">="&$B12,inc_date,"<="&$C12) | L12: =SUMIFS(inc_fama,inc_date,">="&$B12,inc_date,"<="&$C12)+SUMIFS(inc_ac,inc_date,">="&$B12,inc_date,"<="&$C12) | M12: =SUMIFS(inc_civ_k,inc_date,">="&$B12,inc_date,"<="&$C12) | N12: =SUM($K$5:K12) | Q12: Civils blessés | R12: =SUMIFS(inc_civ_w,inc_periode,"P1") | S12: =SUMIFS(inc_civ_w,inc_periode,"P2") | T12: =S12-R12 | U12: =IF(R12=0,"—",(S12-R12)/R12)
B13: 46321 | C13: =B13+6 | D13: ="S"&WEEKNUM(B13,21) | E13: =COUNTIFS(inc_acteur,E$4,inc_date,">="&$B13,inc_date,"<="&$C13) | F13: =COUNTIFS(inc_acteur,F$4,inc_date,">="&$B13,inc_date,"<="&$C13) | G13: =COUNTIFS(inc_acteur,G$4,inc_date,">="&$B13,inc_date,"<="&$C13) | H13: =COUNTIFS(inc_acteur,H$4,inc_date,">="&$B13,inc_date,"<="&$C13) | I13: =COUNTIFS(inc_acteur,I$4,inc_date,">="&$B13,inc_date,"<="&$C13) | J13: =SUM(E13:I13) | K13: =SUMIFS(inc_tues,inc_date,">="&$B13,inc_date,"<="&$C13) | L13: =SUMIFS(inc_fama,inc_date,">="&$B13,inc_date,"<="&$C13)+SUMIFS(inc_ac,inc_date,">="&$B13,inc_date,"<="&$C13) | M13: =SUMIFS(inc_civ_k,inc_date,">="&$B13,inc_date,"<="&$C13) | N13: =SUM($K$5:K13) | Q13: Capturés | R13: =SUMIFS(inc_pow,inc_periode,"P1") | S13: =SUMIFS(inc_pow,inc_periode,"P2") | T13: =S13-R13 | U13: =IF(R13=0,"—",(S13-R13)/R13)
Q14: Véhicules / aéronefs détruits | R14: =SUMIFS(inc_vehd,inc_periode,"P1") | S14: =SUMIFS(inc_vehd,inc_periode,"P2") | T14: =S14-R14 | U14: =IF(R14=0,"—",(S14-R14)/R14)
Q15: Incidents dans le rayon de Bamako | R15: =COUNTIFS(inc_periode,"P1",inc_rayon,"Oui") | S15: =COUNTIFS(inc_periode,"P2",inc_rayon,"Oui") | T15: =S15-R15 | U15: =IF(R15=0,"—",(S15-R15)/R15)
Q16: Rouge : hausse ; vert : baisse. La baisse des pertes FAMa en P2 tient surtout à l'effet Dioura (150 tués le 10/09).

Sheet MODES_CIBLES
A1: Modes opératoires et cibles | L1: ◄ Accueil
A2: Fréquence, létalité et matrice mode × cible.
B4: Mode opératoire | C4: Incidents | D4: Part | E4: Tués | F4: Tués par incident | G4: Civils tués | H4: Dans le rayon Bamako | J4: Mode × cible | K4: FAMa / Africa Corps | L4: Civils | M4: Groupes armés | N4: Milices pro-gouv. | O4: Logistique civile
B5: Embuscade | C5: =COUNTIFS(inc_mode,$B5) | D5: =IF(SUM($C$5:$C$16)=0,0,C5/SUM($C$5:$C$16)) | E5: =SUMIFS(inc_tues,inc_mode,$B5) | F5: =IF(C5=0,0,E5/C5) | G5: =SUMIFS(inc_civ_k,inc_mode,$B5) | H5: =COUNTIFS(inc_mode,$B5,inc_rayon,"Oui") | J5: =B5 | K5: =COUNTIFS(inc_mode,$J5,inc_cible,K$4) | L5: =COUNTIFS(inc_mode,$J5,inc_cible,L$4) | M5: =COUNTIFS(inc_mode,$J5,inc_cible,M$4) | N5: =COUNTIFS(inc_mode,$J5,inc_cible,N$4) | O5: =COUNTIFS(inc_mode,$J5,inc_cible,O$4)
B6: Attaque de poste / camp | C6: =COUNTIFS(inc_mode,$B6) | D6: =IF(SUM($C$5:$C$16)=0,0,C6/SUM($C$5:$C$16)) | E6: =SUMIFS(inc_tues,inc_mode,$B6) | F6: =IF(C6=0,0,E6/C6) | G6: =SUMIFS(inc_civ_k,inc_mode,$B6) | H6: =COUNTIFS(inc_mode,$B6,inc_rayon,"Oui") | J6: =B6 | K6: =COUNTIFS(inc_mode,$J6,inc_cible,K$4) | L6: =COUNTIFS(inc_mode,$J6,inc_cible,L$4) | M6: =COUNTIFS(inc_mode,$J6,inc_cible,M$4) | N6: =COUNTIFS(inc_mode,$J6,inc_cible,N$4) | O6: =COUNTIFS(inc_mode,$J6,inc_cible,O$4)
B7: Frappe aérienne étatique | C7: =COUNTIFS(inc_mode,$B7) | D7: =IF(SUM($C$5:$C$16)=0,0,C7/SUM($C$5:$C$16)) | E7: =SUMIFS(inc_tues,inc_mode,$B7) | F7: =IF(C7=0,0,E7/C7) | G7: =SUMIFS(inc_civ_k,inc_mode,$B7) | H7: =COUNTIFS(inc_mode,$B7,inc_rayon,"Oui") | J7: =B7 | K7: =COUNTIFS(inc_mode,$J7,inc_cible,K$4) | L7: =COUNTIFS(inc_mode,$J7,inc_cible,L$4) | M7: =COUNTIFS(inc_mode,$J7,inc_cible,M$4) | N7: =COUNTIFS(inc_mode,$J7,inc_cible,N$4) | O7: =COUNTIFS(inc_mode,$J7,inc_cible,O$4)
B8: EEI | C8: =COUNTIFS(inc_mode,$B8) | D8: =IF(SUM($C$5:$C$16)=0,0,C8/SUM($C$5:$C$16)) | E8: =SUMIFS(inc_tues,inc_mode,$B8) | F8: =IF(C8=0,0,E8/C8) | G8: =SUMIFS(inc_civ_k,inc_mode,$B8) | H8: =COUNTIFS(inc_mode,$B8,inc_rayon,"Oui") | J8: =B8 | K8: =COUNTIFS(inc_mode,$J8,inc_cible,K$4) | L8: =COUNTIFS(inc_mode,$J8,inc_cible,L$4) | M8: =COUNTIFS(inc_mode,$J8,inc_cible,M$4) | N8: =COUNTIFS(inc_mode,$J8,inc_cible,N$4) | O8: =COUNTIFS(inc_mode,$J8,inc_cible,O$4)
B9: Drone armé (FPV) | C9: =COUNTIFS(inc_mode,$B9) | D9: =IF(SUM($C$5:$C$16)=0,0,C9/SUM($C$5:$C$16)) | E9: =SUMIFS(inc_tues,inc_mode,$B9) | F9: =IF(C9=0,0,E9/C9) | G9: =SUMIFS(inc_civ_k,inc_mode,$B9) | H9: =COUNTIFS(inc_mode,$B9,inc_rayon,"Oui") | J9: =B9 | K9: =COUNTIFS(inc_mode,$J9,inc_cible,K$4) | L9: =COUNTIFS(inc_mode,$J9,inc_cible,L$4) | M9: =COUNTIFS(inc_mode,$J9,inc_cible,M$4) | N9: =COUNTIFS(inc_mode,$J9,inc_cible,N$4) | O9: =COUNTIFS(inc_mode,$J9,inc_cible,O$4)
B10: Affrontement JNIM–EIS | C10: =COUNTIFS(inc_mode,$B10) | D10: =IF(SUM($C$5:$C$16)=0,0,C10/SUM($C$5:$C$16)) | E10: =SUMIFS(inc_tues,inc_mode,$B10) | F10: =IF(C10=0,0,E10/C10) | G10: =SUMIFS(inc_civ_k,inc_mode,$B10) | H10: =COUNTIFS(inc_mode,$B10,inc_rayon,"Oui") | J10: =B10 | K10: =COUNTIFS(inc_mode,$J10,inc_cible,K$4) | L10: =COUNTIFS(inc_mode,$J10,inc_cible,L$4) | M10: =COUNTIFS(inc_mode,$J10,inc_cible,M$4) | N10: =COUNTIFS(inc_mode,$J10,inc_cible,N$4) | O10: =COUNTIFS(inc_mode,$J10,inc_cible,O$4)
B11: Perte d'aéronef (accident) | C11: =COUNTIFS(inc_mode,$B11) | D11: =IF(SUM($C$5:$C$16)=0,0,C11/SUM($C$5:$C$16)) | E11: =SUMIFS(inc_tues,inc_mode,$B11) | F11: =IF(C11=0,0,E11/C11) | G11: =SUMIFS(inc_civ_k,inc_mode,$B11) | H11: =COUNTIFS(inc_mode,$B11,inc_rayon,"Oui") | J11: =B11 | K11: =COUNTIFS(inc_mode,$J11,inc_cible,K$4) | L11: =COUNTIFS(inc_mode,$J11,inc_cible,L$4) | M11: =COUNTIFS(inc_mode,$J11,inc_cible,M$4) | N11: =COUNTIFS(inc_mode,$J11,inc_cible,N$4) | O11: =COUNTIFS(inc_mode,$J11,inc_cible,O$4)
B12: Attaque ciblée / VIP | C12: =COUNTIFS(inc_mode,$B12) | D12: =IF(SUM($C$5:$C$16)=0,0,C12/SUM($C$5:$C$16)) | E12: =SUMIFS(inc_tues,inc_mode,$B12) | F12: =IF(C12=0,0,E12/C12) | G12: =SUMIFS(inc_civ_k,inc_mode,$B12) | H12: =COUNTIFS(inc_mode,$B12,inc_rayon,"Oui") | J12: =B12 | K12: =COUNTIFS(inc_mode,$J12,inc_cible,K$4) | L12: =COUNTIFS(inc_mode,$J12,inc_cible,L$4) | M12: =COUNTIFS(inc_mode,$J12,inc_cible,M$4) | N12: =COUNTIFS(inc_mode,$J12,inc_cible,N$4) | O12: =COUNTIFS(inc_mode,$J12,inc_cible,O$4)
B13: Offensive terrestre | C13: =COUNTIFS(inc_mode,$B13) | D13: =IF(SUM($C$5:$C$16)=0,0,C13/SUM($C$5:$C$16)) | E13: =SUMIFS(inc_tues,inc_mode,$B13) | F13: =IF(C13=0,0,E13/C13) | G13: =SUMIFS(inc_civ_k,inc_mode,$B13) | H13: =COUNTIFS(inc_mode,$B13,inc_rayon,"Oui") | J13: =B13 | K13: =COUNTIFS(inc_mode,$J13,inc_cible,K$4) | L13: =COUNTIFS(inc_mode,$J13,inc_cible,L$4) | M13: =COUNTIFS(inc_mode,$J13,inc_cible,M$4) | N13: =COUNTIFS(inc_mode,$J13,inc_cible,N$4) | O13: =COUNTIFS(inc_mode,$J13,inc_cible,O$4)
B14: Sabotage logistique | C14: =COUNTIFS(inc_mode,$B14) | D14: =IF(SUM($C$5:$C$16)=0,0,C14/SUM($C$5:$C$16)) | E14: =SUMIFS(inc_tues,inc_mode,$B14) | F14: =IF(C14=0,0,E14/C14) | G14: =SUMIFS(inc_civ_k,inc_mode,$B14) | H14: =COUNTIFS(inc_mode,$B14,inc_rayon,"Oui") | J14: =B14 | K14: =COUNTIFS(inc_mode,$J14,inc_cible,K$4) | L14: =COUNTIFS(inc_mode,$J14,inc_cible,L$4) | M14: =COUNTIFS(inc_mode,$J14,inc_cible,M$4) | N14: =COUNTIFS(inc_mode,$J14,inc_cible,N$4) | O14: =COUNTIFS(inc_mode,$J14,inc_cible,O$4)
B15: Lutte anti-drone | C15: =COUNTIFS(inc_mode,$B15) | D15: =IF(SUM($C$5:$C$16)=0,0,C15/SUM($C$5:$C$16)) | E15: =SUMIFS(inc_tues,inc_mode,$B15) | F15: =IF(C15=0,0,E15/C15) | G15: =SUMIFS(inc_civ_k,inc_mode,$B15) | H15: =COUNTIFS(inc_mode,$B15,inc_rayon,"Oui") | J15: =B15 | K15: =COUNTIFS(inc_mode,$J15,inc_cible,K$4) | L15: =COUNTIFS(inc_mode,$J15,inc_cible,L$4) | M15: =COUNTIFS(inc_mode,$J15,inc_cible,M$4) | N15: =COUNTIFS(inc_mode,$J15,inc_cible,N$4) | O15: =COUNTIFS(inc_mode,$J15,inc_cible,O$4)
B16: Tirs indirects | C16: =COUNTIFS(inc_mode,$B16) | D16: =IF(SUM($C$5:$C$16)=0,0,C16/SUM($C$5:$C$16)) | E16: =SUMIFS(inc_tues,inc_mode,$B16) | F16: =IF(C16=0,0,E16/C16) | G16: =SUMIFS(inc_civ_k,inc_mode,$B16) | H16: =COUNTIFS(inc_mode,$B16,inc_rayon,"Oui") | J16: =B16 | K16: =COUNTIFS(inc_mode,$J16,inc_cible,K$4) | L16: =COUNTIFS(inc_mode,$J16,inc_cible,L$4) | M16: =COUNTIFS(inc_mode,$J16,inc_cible,M$4) | N16: =COUNTIFS(inc_mode,$J16,inc_cible,N$4) | O16: =COUNTIFS(inc_mode,$J16,inc_cible,O$4)

Sheet PRESSION_BAMAKO
A1: Pression sur Bamako | J1: ◄ Accueil
A2: Distance orthodromique de chaque incident au centre de Bamako (formule de haversine, voir INCIDENTS).
B4: Tranche de distance | C4: De (km) | D4: À (km) | E4: Incidents | F4: dont JNIM | G4: Tués | H4: Part des incidents
B5: =C5&" – "&D5&" km" | C5: 0 | D5: 50 | E5: =COUNTIFS(inc_dist,">="&C5,inc_dist,"<"&D5) | F5: =COUNTIFS(inc_dist,">="&C5,inc_dist,"<"&D5,inc_acteur,"JNIM") | G5: =SUMIFS(inc_tues,inc_dist,">="&C5,inc_dist,"<"&D5) | H5: =IF(SUM($E$5:$E$10)=0,0,E5/SUM($E$5:$E$10))
B6: =C6&" – "&D6&" km" | C6: 50 | D6: 150 | E6: =COUNTIFS(inc_dist,">="&C6,inc_dist,"<"&D6) | F6: =COUNTIFS(inc_dist,">="&C6,inc_dist,"<"&D6,inc_acteur,"JNIM") | G6: =SUMIFS(inc_tues,inc_dist,">="&C6,inc_dist,"<"&D6) | H6: =IF(SUM($E$5:$E$10)=0,0,E6/SUM($E$5:$E$10))
B7: =C7&" – "&D7&" km" | C7: 150 | D7: 300 | E7: =COUNTIFS(inc_dist,">="&C7,inc_dist,"<"&D7) | F7: =COUNTIFS(inc_dist,">="&C7,inc_dist,"<"&D7,inc_acteur,"JNIM") | G7: =SUMIFS(inc_tues,inc_dist,">="&C7,inc_dist,"<"&D7) | H7: =IF(SUM($E$5:$E$10)=0,0,E7/SUM($E$5:$E$10))
B8: =C8&" – "&D8&" km" | C8: 300 | D8: 500 | E8: =COUNTIFS(inc_dist,">="&C8,inc_dist,"<"&D8) | F8: =COUNTIFS(inc_dist,">="&C8,inc_dist,"<"&D8,inc_acteur,"JNIM") | G8: =SUMIFS(inc_tues,inc_dist,">="&C8,inc_dist,"<"&D8) | H8: =IF(SUM($E$5:$E$10)=0,0,E8/SUM($E$5:$E$10))
B9: =C9&" – "&D9&" km" | C9: 500 | D9: 800 | E9: =COUNTIFS(inc_dist,">="&C9,inc_dist,"<"&D9) | F9: =COUNTIFS(inc_dist,">="&C9,inc_dist,"<"&D9,inc_acteur,"JNIM") | G9: =SUMIFS(inc_tues,inc_dist,">="&C9,inc_dist,"<"&D9) | H9: =IF(SUM($E$5:$E$10)=0,0,E9/SUM($E$5:$E$10))
B10: ="Plus de "&C10&" km" | C10: 800 | D10: 2000 | E10: =COUNTIFS(inc_dist,">="&C10,inc_dist,"<"&D10) | F10: =COUNTIFS(inc_dist,">="&C10,inc_dist,"<"&D10,inc_acteur,"JNIM") | G10: =SUMIFS(inc_tues,inc_dist,">="&C10,inc_dist,"<"&D10) | H10: =IF(SUM($E$5:$E$10)=0,0,E10/SUM($E$5:$E$10))
B11: Bornes « De / À » modifiables (en bleu).
B13: Incidents dans le rayon de Bamako (à la génération du classeur, triés par distance)
B14: ID | C14: Date | D14: Localité | E14: Cercle | F14: Instigateur | G14: Mode | H14: Distance (km) | I14: Tués
B15: =INCIDENTS!A12 | C15: =INCIDENTS!B12 | D15: =INCIDENTS!I12 | E15: =INCIDENTS!G12 | F15: =INCIDENTS!O12 | G15: =INCIDENTS!N12 | H15: =INCIDENTS!AE12 | I15: =INCIDENTS!Y12
B16: =INCIDENTS!A5 | C16: =INCIDENTS!B5 | D16: =INCIDENTS!I5 | E16: =INCIDENTS!G5 | F16: =INCIDENTS!O5 | G16: =INCIDENTS!N5 | H16: =INCIDENTS!AE5 | I16: =INCIDENTS!Y5
B17: =INCIDENTS!A32 | C17: =INCIDENTS!B32 | D17: =INCIDENTS!I32 | E17: =INCIDENTS!G32 | F17: =INCIDENTS!O32 | G17: =INCIDENTS!N32 | H17: =INCIDENTS!AE32 | I17: =INCIDENTS!Y32
B18: =INCIDENTS!A9 | C18: =INCIDENTS!B9 | D18: =INCIDENTS!I9 | E18: =INCIDENTS!G9 | F18: =INCIDENTS!O9 | G18: =INCIDENTS!N9 | H18: =INCIDENTS!AE9 | I18: =INCIDENTS!Y9
B19: =INCIDENTS!A31 | C19: =INCIDENTS!B31 | D19: =INCIDENTS!I31 | E19: =INCIDENTS!G31 | F19: =INCIDENTS!O31 | G19: =INCIDENTS!N31 | H19: =INCIDENTS!AE31 | I19: =INCIDENTS!Y31
B20: =INCIDENTS!A13 | C20: =INCIDENTS!B13 | D20: =INCIDENTS!I13 | E20: =INCIDENTS!G13 | F20: =INCIDENTS!O13 | G20: =INCIDENTS!N13 | H20: =INCIDENTS!AE13 | I20: =INCIDENTS!Y13
B21: =INCIDENTS!A22 | C21: =INCIDENTS!B22 | D21: =INCIDENTS!I22 | E21: =INCIDENTS!G22 | F21: =INCIDENTS!O22 | G21: =INCIDENTS!N22 | H21: =INCIDENTS!AE22 | I21: =INCIDENTS!Y22
B22: =INCIDENTS!A24 | C22: =INCIDENTS!B24 | D22: =INCIDENTS!I24 | E22: =INCIDENTS!G24 | F22: =INCIDENTS!O24 | G22: =INCIDENTS!N24 | H22: =INCIDENTS!AE24 | I22: =INCIDENTS!Y24
B23: =INCIDENTS!A18 | C23: =INCIDENTS!B18 | D23: =INCIDENTS!I18 | E23: =INCIDENTS!G18 | F23: =INCIDENTS!O18 | G23: =INCIDENTS!N18 | H23: =INCIDENTS!AE18 | I23: =INCIDENTS!Y18

Sheet EVALUATION
A1: Évaluation stratégique | H1: ◄ Accueil
A2: Jugements établis sur l'ensemble de la base. « Probable » = 55–80 % ; « très probable » = plus de 80 %.
B4: Jugements clés
B5: Réf. | C5: Jugement | D5: Analyse | E5: Niveau de confiance
B6: JC1 | C6: Campagne d'usure méthodique du JNIM | D6: Le JNIM vise les emprises isolées et les axes du Mali central. La prise du camp de Dioura (10/09 : 150 FAMa tués, 93 capturés, 115 véhicules détruits) concentre à elle seule 72 % des pertes FAMa de la période. | E6: Modérée (bilan issu en partie d'AzZalaqa)
B7: JC2 | C7: Étau autour de Bamako | D7: Kassela (32 km), axe Mourdja–Kaloumba, Ségou–Fana, Dougabougou–Markala : l'incendie de citernes et les embuscades de convois relèvent très probablement d'une stratégie de blocus économique de la capitale. | E7: Élevée
B8: JC3 | C8: Ouverture d'un front sud | D8: La prise d'un poste à Kourouma (Sikasso, 07/10, ≈ 46 km de la frontière burkinabè) indique une capacité d'action dans le couloir Sikasso–Bobo-Dioulasso, à la porte des États côtiers. | E8: Modérée (un seul événement)
B9: JC4 | C9: Rivalité JNIM – EI-Sahel | D9: Dans le Liptako-Gourma, elle atteint une intensité inédite (200 puis 400 tués revendiqués). L'EI-Sahel s'en sert probablement pour consolider la bande frontalière Gourma–Oudalan–Ménaka. | E9: Faible sur les bilans
B10: JC5 | C10: Initiative au nord, attrition aérienne | D10: Les FAMa et Africa Corps ont repris Kidal (10/10), mais perdent des moyens aériens (hélicoptère, drone MALE Orion, drone Molniya-2 abattu, drones endommagés à Sévaré) et voient monter les victimes civiles de leurs frappes. Le FLA conserve, de façon très probable, une capacité de harcèlement par drones FPV. | E10: Modérée
B11: JC6 | C11: Dommages civils : risque stratégique majeur | D11: Les frappes de Guèllèdjè, Tieri, Nzanakoro et Tombouctou causent 100 % des civils tués recensés. Elles nourrissent le récit du JNIM auprès des communautés peules et nomades, et donc son recrutement. | E11: Élevée
B13: Scénarios à 30–60 jours (horizon fin décembre 2026)
C14: Scénario | D14: Description | E14: Probabilité
C15: Le plus probable Usure prolongée au centre | D15: Le JNIM maintient 3 à 5 incidents par semaine à Ségou et Mopti (embuscades, EEI, postes isolés) et entrave les convois vers Bamako. Les FAMa et Africa Corps consolident Kidal et intensifient les frappes, avec des dommages civils récurrents. | E15: 55–65 %
C16: Le plus dangereux Coup d'éclat contre un centre névralgique | D16: Attaque complexe contre une emprise majeure (type Dioura / Sévaré) ou la périphérie de Bamako (cercle de Kati), avec tirs indirects ou drones. Elle s'accompagne d'un durcissement du blocus des axes et d'une montée du front sud (Sikasso, frontières BF et CI). | E16: 15–25 %
C17: Alternatif Poussée de l'EI-Sahel à l'est | D17: L'EI-Sahel exploite l'affaiblissement local du JNIM pour s'étendre vers Ménaka, Ansongo et Tessit et dans le Gourma. Il multiplie les embuscades contre les convois FAMa pendant que le FLA mène une guérilla par drones au nord. | E17: ≈ 20 %
B19: Indicateurs d'alerte à surveiller
C20: Indicateur | D20: Ce qu'il signalerait | E20: Zone
B21: IA1 | C21: Nouvelles attaques de citernes ou de convois commerciaux | D21: Durcissement du blocus logistique de Bamako | E21: Ségou–Fana, Markala, axes d'entrée de Bamako
B22: IA2 | C22: Incidents dans les cercles de Kati, Kolokani ou Banamba | D22: Encerclement rapproché de la capitale | E22: Koulikoro
B23: IA3 | C23: Tirs indirects ou drones contre aéroports et bases | D23: Ciblage du capacitaire aérien et ISR | E23: Sévaré, Gao, Tombouctou, Kidal
B24: IA4 | C24: Usage de drones FPV par le JNIM | D24: Diffusion technologique depuis le FLA | E24: Centre et Nord
B25: IA5 | C25: Attaques de postes au sud de Sikasso | D25: Ouverture d'un couloir vers le Golfe de Guinée | E25: Kadiolo, Kourouma, frontières BF / CI
B26: IA6 | C26: Revendications de l'EI-Sahel à Ménaka ou Ansongo | D26: Expansion de l'EI-Sahel vers l'ouest | E26: Gao, Ménaka
